Workbook
Name _TAB1: '[1]Icc 2'!$B$9:$F$23
Name _TAB2: '[1]Icc 2'!$B$29:$F$43
Name AA: #REF!
Name AB: #REF!
Name AC: #REF!
Name AD: #REF!
Name ADD: #REF!
Name AE: #REF!
Name AF: #REF!
Name AG: #REF!
Name AH: #REF!
Name AJ: #REF!
Name AK: #REF!
Name AL: #REF!
Name AM: #REF!
Name AN: #REF!
Name AP: #REF!
Name AQ: #REF!
Name AR: #REF!
Name AS: #REF!
Name BA: #REF!
Name BB: #REF!
Name BC: #REF!
Name BD: #REF!
Name BE: #REF!
Name CA: #REF!
Name CB: #REF!
Name DISJ: [1]Tabela!$P$77:$R$99
Name JASolar: #REF!
Name Marcas: #REF!
Name Matriz: [1]Tabela!#REF!
Name ModoD: [1]Tabela!$A$6:$AG$14
Name REF_INST: '[2]Q 52H'!$C$2:$C$45
Name REF_INST: '[2]Q 52H'!$C$2:$C$45
Name REF_INST: '[3]Q 52H'!$C$2:$C$45
Name Risen: #REF!
Name TAB52C1: CABOS!$E$17:$H$33
Name TAB52C11: CABOS!$E$412:$L$430
Name TAB52C12: CABOS!$E$450:$L$467
Name TAB52C13: CABOS!$E$488:$I$503
Name TAB52C14: CABOS!$E$537:$I$552
Name TAB52C2: CABOS!$E$67:$H$82
Name TAB52C3: CABOS!$E$116:$H$131
Name TAB52C30: CABOS!$E$579:$I$594
Name TAB52C4: CABOS!$E$163:$H$178
Name TAB52C5: CABOS!$E$216:$I$230
Name TAB52C6: CABOS!$E$251:$H$265
Name TAB52C7: CABOS!$E$291:$J$305
Name TAB52C8: CABOS!$E$338:$J$352
Name TAB52C9: CABOS!$E$373:$L$391
Name Tabela1: [1]Tabela!$P$19:$Q$31
Name x: #REF!
Name ZNShine: #REF!

Sheet Dados (ALTERAR)
B2: Projetista Responsável | C2: Ricardo Miguel Modesto Louro
B3: nº O.E. | C3: =IF(C2="Rui Bárbaro Bernardes",39000,IF(C2="João Duarte Marques Serrasqueiro",17762,IF(C2="João Sinfrónio",16733,IF(C2="Ricardo Miguel Modesto Louro",31306,IF(C2="Duarte Miguel Saraiva Batista",30250,0))))) -> 31306
B4: Data (Mês de Ano) | C4: 46235
B6: Dados Empresa
B7: Nome | C7: STA – Sociedade Transformadora de Alumínios S.A.
B8: Morada | C8: R. Terramonte 771, Gueifães, 4470-122 Maia
B9: Coordenada GPS | C9: 41.20583976494613, -8.603993799425119
B10: Telefone | C10: 912101956
B11: email | C11: Branco@sofi.pt
B12: NIF
B13: CPE
B14: Tensão de alimentação (kV)
B15: Potência certificada (kW)
B16: Tipo de empresa
B18: Características Gerais
B19: Nr de registo
B20: Potência Nominal (kW) | C20: 50
B21: Potência de ligação (kW) | C21: 34
B22: Injeção na rede
B23: Nº total de inversores | C23: 34
B24: Potência dos geradores (kWp) | C24: 34
B25: Nº total de painéis | C25: 34
B26: Tipo de Instalação
B27: Ponto de Injeção | C27: Quadro de Entrada
B29: Caracteristicas Painel | F29: Cálculo da secção mínima DC
B30: Marca | C30: Risen | F30: Queda de tensão admitida (%) | G30: 0.03
B31: Modelo | C31: RSM144-9-565BNDG-585BNDG | F31: Comprimento do cabo (m)
B32: Potência Pico (Wp) | C32: =VLOOKUP(B32,'Paineís (Não Alterar)'!$A$3:$J$14,MATCH('Dados (ALTERAR)'!$C$31,'Paineís (Não Alterar)'!$A$2:$J$2,0),FALSE) -> 585 | F32: Secção cabo (mm2) | G32: 6
B33: Nº de células | C33: =VLOOKUP(B33,'Paineís (Não Alterar)'!$A$3:$J$14,MATCH('Dados (ALTERAR)'!$C$31,'Paineís (Não Alterar)'!$A$2:$J$2,0),FALSE) -> 144
B34: Tensão nominal (V) | C34: =VLOOKUP(B34,'Paineís (Não Alterar)'!$A$3:$J$14,MATCH('Dados (ALTERAR)'!$C$31,'Paineís (Não Alterar)'!$A$2:$J$2,0),FALSE) -> 44
B35: Corrente nominal (A) | C35: =VLOOKUP(B35,'Paineís (Não Alterar)'!$A$3:$J$14,MATCH('Dados (ALTERAR)'!$C$31,'Paineís (Não Alterar)'!$A$2:$J$2,0),FALSE) -> 13.32
B36: Tensão circuito aberto (V) | C36: =VLOOKUP(B36,'Paineís (Não Alterar)'!$A$3:$J$14,MATCH('Dados (ALTERAR)'!$C$31,'Paineís (Não Alterar)'!$A$2:$J$2,0),FALSE) -> 52.37
B37: Corrente curto-circuito (A) | C37: =VLOOKUP(B37,'Paineís (Não Alterar)'!$A$3:$J$14,MATCH('Dados (ALTERAR)'!$C$31,'Paineís (Não Alterar)'!$A$2:$J$2,0),FALSE) -> 14.18
B38: Coeficiente de temperatura para Voc (%/°C) | C38: =VLOOKUP(B38,'Paineís (Não Alterar)'!$A$3:$J$14,MATCH('Dados (ALTERAR)'!$C$31,'Paineís (Não Alterar)'!$A$2:$J$2,0),FALSE) -> -0.25
B39: Coeficiente de temperatura para Isc (%/°C) | C39: =VLOOKUP(B39,'Paineís (Não Alterar)'!$A$3:$J$14,MATCH('Dados (ALTERAR)'!$C$31,'Paineís (Não Alterar)'!$A$2:$J$2,0),FALSE) -> 0.046
B40: Coeficiente de temperatura para Pmpp (%/°C) | C40: =VLOOKUP(B40,'Paineís (Não Alterar)'!$A$3:$J$14,MATCH('Dados (ALTERAR)'!$C$31,'Paineís (Não Alterar)'!$A$2:$J$2,0),FALSE) -> -0.29
B41: Temperatura mínima no local (°C) | C41: =VLOOKUP(B41,'Paineís (Não Alterar)'!$A$3:$J$14,MATCH('Dados (ALTERAR)'!$C$31,'Paineís (Não Alterar)'!$A$2:$J$2,0),FALSE) -> -40
B42: Eficiência Máxima | C42: =VLOOKUP(B42,'Paineís (Não Alterar)'!$A$3:$J$14,MATCH('Dados (ALTERAR)'!$C$31,'Paineís (Não Alterar)'!$A$2:$J$2,0),FALSE) -> 22.7
B43: Eficiência aos 25 anos | C43: =VLOOKUP(B43,'Paineís (Não Alterar)'!$A$3:$J$14,MATCH('Dados (ALTERAR)'!$C$31,'Paineís (Não Alterar)'!$A$2:$J$2,0),FALSE) -> 89.4
B45: Caracteristicas Inversor | F45: Configuração de Strings
...

Sheet Cálculos Elétricos
BK5: Al | BL5: 0.029
BK6: Cobre | BL6: 0.018
A7: Origem | B7: Potência (kW) | C7: Destino | D7: Tipo Circuito | E7: Nº Paineis | F7: Tensão | G7: Pmax | H7: Cos | I7: Angulo | J7: S | K7: IB | L7: Factor de Simultaneadade | M7: IB | N7: Canalização | AF7: Quantidade de Condutor (m) | AI7: IZ | AM7: Factor de Correcão | BC7: IZ | BD7: Dispos. | BE7: Norma | BF7: In (A) | BG7: K2 | BH7: I2 | BI7: Condição de Aquecimento | BJ7: Condição de Sobrecarga | BQ7: b | BR7: u (V) | BS7: Du (%) | BT7: QDT Total | BU7: 0.03 | BV7: Isolamento | BW7: Preço € Fases | BX7: Preço € Neutro | BY7: Preço € Terra | BZ7: Preço € Total
F8: U | H8: F | J8: Inst | N8: Designação | V8: L (m) | W8: L (m) + | X8: Materiais | Z8: Sf | AB8: SN | AD8: SPE | AF8: Sf | AG8: SN | AH8: SPE | AI8: Tabela | AK8: Total | AL8: Quadro | AM8: Quadro | AN8: FC1 | AO8: Quadro | AP8: FC2 | AQ8: Quadro | AR8: FC3 | AS8: Quadro | AT8: FC4 | AU8: Quadro | AV8: FC5 | AW8: Quadro | AX8: FC6 | AY8: Quadro | AZ8: FC7 | BA8: Quadro | BB8: FC8 | BC8: (corr.) | BD8: Protec. | BE8: Dispos. | BH8: (K2.In) | BK8: r | BL8: 1.25 | BM8: 1.5 | BN8: l | BO8: sin 𝞿 | BU8: Verificação
F9: (V) | G9: (W) | J9: VA | K9: (A) | M9: (A) | N9: Mono/Multi | O9: Cabo | P9: Situação | Q9: Modos de instalação | R9: Métodos de Refência Disponíveis | S9: Refª | T9: Métodos de Refºª | U9: Métodos de Refºª Escolhido | W9: 0.2 | X9: Alma | Y9: Isol. | Z9: Secção | AA9: Nº cabos | AB9: Secção | AC9: Nº cabos | AD9: Secção | AE9: Nº cabos | AI9: (A) | AJ9: Factor | AK9: (A) | AL9: RTIEBT | AM9: RTIEBT | AO9: RTIEBT | AQ9: RTIEBT | AS9: RTIEBT | AU9: RTIEBT | AW9: RTIEBT | AY9: RTIEBT | BA9: RTIEBT | BC9: (A) | BE9: Protec. | BH9: (A) | BI9: Ib<In<Iz | BJ9: I2<1,45Iz | BK9: W.mm2/m | BL9: Iccmax | BM9: Icc min | BQ9: (mon=2/ trif = 1) | BT9: (%) | BU9: %<%a
A10: Inversor 1 | B10: 100 | C10: QPV | D10: Trif. Equilibrado | F10: =VLOOKUP('Cálculos Elétricos'!D10,'Tabelas de apoio'!$H$20:$K$24,2,FALSE) -> 400 | G10: =B10*1100 -> 110000 | H10: 1 | I10: =DEGREES(ACOS(H10)) -> 0 | J10: =G10 -> 110000 | K10: =IF(D10="Monofásico",(J10)/(F10*H10),IF(F10=400,(J10)/(SQRT(3)*F10),IF(D10="DC",#REF!, "ERRO"))) -> 158.77132 | L10: 1 | M10: =L10*K10 -> 158.77132 | N10: Monocondutor | O10: LXV | P10: À vista | Q10: Caminhos de cabos, escadas e consolas | R10: =INDEX('Tabelas de apoio'!$I$9:$P$15,MATCH(P10,'Tabelas de apoio'!$H$9:$H$15,0),MATCH(Q10,'Tabelas de apoio'!$I$8:$P$8,0)) -> 12,13,13,15,16 | S10: 13 | T10: =VLOOKUP(S10,'Tabelas de apoio'!C5:D49,2) -> E ou F [4](3) | U10: F | V10: 50 | W10: =IF(V10<30,V10+V10*0.2,V10+V10*0.1) -> 55 | X10: =INDEX('Tabelas de apoio'!$I$27:$I$42,MATCH(O10,'Tabelas de apoio'!$H$27:$H$42,0)) -> AL | Y10: =LOOKUP(O10,'Tabelas de apoio'!$I$27:$I$42,'Tabelas de apoio'!$J$27:$J$42) -> XLPE | Z10: 120 | AA10: 1 | AB10: 70 | AC10: 1 | AD10: 70 | AE10: 1 | AF10: =IF(N10="Multicondutor",W10*AA10,3*W10*AA10) -> 165 | AG10: =IF(N10="Multicondutor",0,AC10*W10) -> 55 | AH10: =IF(N10="Multicondutor",0,AE10*W10) -> 55 | AI10: 308 | AJ10: 1 | AK10: =AI10*AA10*AJ10 -> 308 | AL10: Catalogo | AM10: 52-D1 | AN10: 0.96 | AO10: 52-D2 | AP10: 1 | AQ10: 52-E1 | AR10: 0.77 | AS10: 52-E2 | AT10: 1 | AU10: 52-E3 | AV10: 1 | AW10: 52-E4 | AX10: 1 | AY10: 52-E5 | AZ10: 1 | BA10: 52-E6 | BB10: 1 | BC10: =AK10*AN10*AP10*AR10*AT10*AV10*AX10*AZ10*BB10 -> 227.6736 | BD10: Disjuntor | BE10: EN60898 | BF10: 200 | BG10: =IF(BD10="Disjuntor",IF(BE10="EN60898",1.45,1.3),IF(BD10="Fusível",IF(BF10>=16,1.6,IF(AND(BF10>4,BF10<16),1.9,2.1)),"Erro")) -> 1.45 | BH10: =BG10*BF10 -> 290 | BI10: =IF(AND(M10<BF10,BF10<BC10),"OK","erro") -> OK | BJ10: =IF(BH10<(1.45*BC10),"OK","erro") -> OK | BK10: =IF(X10="Cobre",0.0225,IF(X10="Al",0.036,"Erro")) -> 0.036 | BL10: =$BL$5*1.25 -> 0.03625 | BM10: =$BL$5*1.5 -> 0.0435 | BN10: =VLOOKUP(Z10,$BK$41:$BV$59,9,TRUE) -> 0.23446714 | BO10: =SIN(RADIANS(I10)) -> 0 | BQ10: =IF(D10="Trif. Equilibrado",1,2) -> 1 | BR10: =BQ10*(BK10*(W10/Z10)*H10 + BN10*W10*BO10)*(M10/AA10) -> 2.6197268 | BS10: =BR10/230 -> 0.011390117 | BT10: =BS10 -> 0.011390117 | BU10: =IF(BT10<$BU$7,"OK","ERRO") -> OK | BV10: (XV) - Rígido | BW10: {=INDEX(Table1[],MATCH(1,(Z10=Table1[Cabo])*('Cálculos Elétricos'!X10=Table1[Material])*('Cálculos Elétricos'!BV10=Table1[Isolamento])*(N10=Table1[Mono/Multi]),0),5)*AF10} -> #N/A | BX10: {=INDEX(Table1[],MATCH(1,(AB10=Table1[Cabo])*('Cálculos Elétricos'!X10=Table1[Material])*('Cálculos Elétricos'!BV10=Table1[Isolamento])*(N10=Table1[Mono/Multi]),0),5)*AG10} -> #N/A | BY10: {=INDEX(Table1[],MATCH(1,(AD10=Table1[Cabo])*('Cálculos Elétricos'!X10=Table1[Material])*('Cálculos Elétricos'!BV10=Table1[Isolamento])*(N10=Table1[Mono/Multi]),0),5)*AH10} -> #N/A | BZ10: =BW10+BX10+BY10 -> #N/A
A11: Inversor 2 | B11: 100 | C11: QPV | D11: Trif. Equilibrado | F11: =VLOOKUP('Cálculos Elétricos'!D11,'Tabelas de apoio'!$H$20:$K$24,2,FALSE) -> 400 | G11: =B11*1100 -> 110000 | H11: 1 | I11: =DEGREES(ACOS(H11)) -> 0 | J11: =G11 -> 110000 | K11: =IF(D11="Monofásico",(J11)/(F11*H11),IF(F11=400,(J11)/(SQRT(3)*F11),IF(D11="DC",#REF!, "ERRO"))) -> 158.77132 | L11: 1 | M11: =L11*K11 -> 158.77132 | N11: Monocondutor | O11: LXV | P11: À vista | Q11: Caminhos de cabos, escadas e consolas | R11: =INDEX('Tabelas de apoio'!$I$9:$P$15,MATCH(P11,'Tabelas de apoio'!$H$9:$H$15,0),MATCH(Q11,'Tabelas de apoio'!$I$8:$P$8,0)) -> 12,13,13,15,16 | S11: 13 | T11: =VLOOKUP(S11,'Tabelas de apoio'!C6:D50,2) -> E ou F [4](3) | U11: F | V11: 5 | W11: =IF(V11<30,V11+V11*0.2,V11+V11*0.1) -> 6 | X11: =INDEX('Tabelas de apoio'!$I$27:$I$42,MATCH(O11,'Tabelas de apoio'!$H$27:$H$42,0)) -> AL | Y11: =LOOKUP(O11,'Tabelas de apoio'!$I$27:$I$42,'Tabelas de apoio'!$J$27:$J$42) -> XLPE | Z11: 120 | AA11: 1 | AB11: 70 | AC11: 1 | AD11: 70 | AE11: 1 | AF11: =IF(N11="Multicondutor",W11*AA11,3*W11*AA11) -> 18 | AG11: =IF(N11="Multicondutor",0,AC11*W11) -> 6 | AH11: =IF(N11="Multicondutor",0,AE11*W11) -> 6 | AI11: 308 | AJ11: 1 | AK11: =AI11*AA11*AJ11 -> 308 | AL11: Catalogo | AM11: 52-D1 | AN11: 0.96 | AO11: 52-D2 | AP11: 1 | AQ11: 52-E1 | AR11: 0.77 | AS11: 52-E2 | AT11: 1 | AU11: 52-E3 | AV11: 1 | AW11: 52-E4 | AX11: 1 | AY11: 52-E5 | AZ11: 1 | BA11: 52-E6 | BB11: 1 | BC11: =AK11*AN11*AP11*AR11*AT11*AV11*AX11*AZ11*BB11 -> 227.6736 | BD11: Disjuntor | BE11: EN60905 | BF11: 200 | BG11: =IF(BD11="Disjuntor",IF(BE11="EN60898",1.45,1.3),IF(BD11="Fusível",IF(BF11>=16,1.6,IF(AND(BF11>4,BF11<16),1.9,2.1)),"Erro")) -> 1.3 | BH11: =BG11*BF11 -> 260 | BI11: =IF(AND(M11<BF11,BF11<BC11),"OK","erro") -> OK | BJ11: =IF(BH11<(1.45*BC11),"OK","erro") -> OK | BK11: =IF(X11="Cobre",0.0225,IF(X11="Al",0.036,"Erro")) -> 0.036 | BL11: =$BL$5*1.25 -> 0.03625 | BM11: =$BL$5*1.5 -> 0.0435 | BN11: =VLOOKUP(Z11,$BK$41:$BV$59,9,TRUE) -> 0.23446714 | BO11: =SIN(RADIANS(I11)) -> 0 | BQ11: =IF(D11="Trif. Equilibrado",1,2) -> 1 | BR11: =BQ11*(BK11*(W11/Z11)*H11 + BN11*W11*BO11)*(M11/AA11) -> 0.28578838 | BS11: =BR11/230 -> 0.0012425582 | BT11: =BS11 -> 0.0012425582 | BU11: =IF(BT11<$BU$7,"OK","ERRO") -> OK | BV11: (XV) - Rígido | BW11: {=INDEX(Table1[],MATCH(1,(Z11=Table1[Cabo])*('Cálculos Elétricos'!X11=Table1[Material])*('Cálculos Elétricos'!BV11=Table1[Isolamento])*(N11=Table1[Mono/Multi]),0),5)*AF11} -> #N/A | BX11: {=INDEX(Table1[],MATCH(1,(AB11=Table1[Cabo])*('Cálculos Elétricos'!X11=Table1[Material])*('Cálculos Elétricos'!BV11=Table1[Isolamento])*(N11=Table1[Mono/Multi]),0),5)*AG11} -> #N/A | BY11: {=INDEX(Table1[],MATCH(1,(AD11=Table1[Cabo])*('Cálculos Elétricos'!X11=Table1[Material])*('Cálculos Elétricos'!BV11=Table1[Isolamento])*(N11=Table1[Mono/Multi]),0),5)*AH11} -> #N/A | BZ11: =BW11+BX11+BY11 -> #N/A
A12: Inversor 3 | B12: 150 | C12: QPV | D12: Trif. Equilibrado | F12: =VLOOKUP('Cálculos Elétricos'!D12,'Tabelas de apoio'!$H$20:$K$24,2,FALSE) -> 400 | G12: =B12*1100 -> 165000 | H12: 1 | I12: =DEGREES(ACOS(H12)) -> 0 | J12: =G12 -> 165000 | K12: =IF(D12="Monofásico",(J12)/(F12*H12),IF(F12=400,(J12)/(SQRT(3)*F12),IF(D12="DC",#REF!, "ERRO"))) -> 238.15699 | L12: 1 | M12: =L12*K12 -> 238.15699 | N12: Monocondutor | O12: LXV | P12: À vista | Q12: Caminhos de cabos, escadas e consolas | R12: =INDEX('Tabelas de apoio'!$I$9:$P$15,MATCH(P12,'Tabelas de apoio'!$H$9:$H$15,0),MATCH(Q12,'Tabelas de apoio'!$I$8:$P$8,0)) -> 12,13,13,15,16 | S12: 13 | T12: =VLOOKUP(S12,'Tabelas de apoio'!C7:D51,2) -> E ou F [4](3) | U12: F | V12: 35 | W12: =IF(V12<30,V12+V12*0.2,V12+V12*0.1) -> 38.5 | X12: =INDEX('Tabelas de apoio'!$I$27:$I$42,MATCH(O12,'Tabelas de apoio'!$H$27:$H$42,0)) -> AL | Y12: =LOOKUP(O12,'Tabelas de apoio'!$I$27:$I$42,'Tabelas de apoio'!$J$27:$J$42) -> XLPE | Z12: 150 | AA12: 1 | AB12: 95 | AC12: 1 | AD12: 95 | AE12: 1 | AF12: =IF(N12="Multicondutor",W12*AA12,3*W12*AA12) -> 115.5 | AG12: =IF(N12="Multicondutor",0,AC12*W12) -> 38.5 | AH12: =IF(N12="Multicondutor",0,AE12*W12) -> 38.5 | AI12: 358 | AJ12: 1 | AK12: =AI12*AA12*AJ12 -> 358 | AL12: Catalogo | AM12: 52-D1 | AN12: 0.96 | AO12: 52-D2 | AP12: 1 | AQ12: 52-E1 | AR12: 0.77 | AS12: 52-E2 | AT12: 1 | AU12: 52-E3 | AV12: 1 | AW12: 52-E4 | AX12: 1 | AY12: 52-E5 | AZ12: 1 | BA12: 52-E6 | BB12: 1 | BC12: =AK12*AN12*AP12*AR12*AT12*AV12*AX12*AZ12*BB12 -> 264.6336 | BD12: Disjuntor | BE12: EN60905 | BF12: 250 | BG12: =IF(BD12="Disjuntor",IF(BE12="EN60898",1.45,1.3),IF(BD12="Fusível",IF(BF12>=16,1.6,IF(AND(BF12>4,BF12<16),1.9,2.1)),"Erro")) -> 1.3 | BH12: =BG12*BF12 -> 325 | BI12: =IF(AND(M12<BF12,BF12<BC12),"OK","erro") -> OK | BJ12: =IF(BH12<(1.45*BC12),"OK","erro") -> OK | BK12: =IF(X12="Cobre",0.0225,IF(X12="Al",0.036,"Erro")) -> 0.036 | BL12: =$BL$5*1.25 -> 0.03625 | BM12: =$BL$5*1.5 -> 0.0435 | BN12: =VLOOKUP(Z12,$BK$41:$BV$59,9,TRUE) -> 0.23472295 | BO12: =SIN(RADIANS(I12)) -> 0 | BQ12: =IF(D12="Trif. Equilibrado",1,2) -> 1 | BR12: =BQ12*(BK12*(W12/Z12)*H12 + BN12*W12*BO12)*(M12/AA12) -> 2.2005706 | BS12: =BR12/230 -> 0.009567698 | BT12: =BS12 -> 0.009567698 | BU12: =IF(BT12<$BU$7,"OK","ERRO") -> OK | BV12: (XV) - Rígido | BW12: {=INDEX(Table1[],MATCH(1,(Z12=Table1[Cabo])*('Cálculos Elétricos'!X12=Table1[Material])*('Cálculos Elétricos'!BV12=Table1[Isolamento])*(N12=Table1[Mono/Multi]),0),5)*AF12} -> #N/A | BX12: {=INDEX(Table1[],MATCH(1,(AB12=Table1[Cabo])*('Cálculos Elétricos'!X12=Table1[Material])*('Cálculos Elétricos'!BV12=Table1[Isolamento])*(N12=Table1[Mono/Multi]),0),5)*AG12} -> #N/A | BY12: {=INDEX(Table1[],MATCH(1,(AD12=Table1[Cabo])*('Cálculos Elétricos'!X12=Table1[Material])*('Cálculos Elétricos'!BV12=Table1[Isolamento])*(N12=Table1[Mono/Multi]),0),5)*AH12} -> #N/A | BZ12: =BW12+BX12+BY12 -> #N/A
A13: Inversor 4 | B13: 150 | C13: QPV | D13: Trif. Equilibrado | F13: 400 | G13: =B13*1100 -> 165000 | H13: 1 | I13: 0 | J13: =G13 -> 165000 | K13: =IF(D13="Monofásico",(J13)/(F13*H13),IF(F13=400,(J13)/(SQRT(3)*F13),IF(D13="DC",#REF!, "ERRO"))) -> 238.15699 | L13: 1 | M13: =L13*K13 -> 238.15699 | N13: Monocondutor | O13: LXV | P13: À vista | Q13: Caminhos de cabos, escadas e consolas | R13: =INDEX('Tabelas de apoio'!$I$9:$P$15,MATCH(P13,'Tabelas de apoio'!$H$9:$H$15,0),MATCH(Q13,'Tabelas de apoio'!$I$8:$P$8,0)) -> 12,13,13,15,16 | S13: 13 | T13: =VLOOKUP(S13,'Tabelas de apoio'!C8:D52,2) -> E ou F [4](3) | U13: F | V13: 15 | W13: 8.4 | X13: =INDEX('Tabelas de apoio'!$I$27:$I$42,MATCH(O13,'Tabelas de apoio'!$H$27:$H$42,0)) -> AL | Y13: XLPE | Z13: 150 | AA13: 1 | AB13: 95 | AC13: 1 | AD13: 95 | AE13: 1 | AF13: =IF(N13="Multicondutor",W13*AA13,3*W13*AA13) -> 25.2 | AG13: =IF(N13="Multicondutor",0,AC13*W13) -> 8.4 | AH13: =IF(N13="Multicondutor",0,AE13*W13) -> 8.4 | AI13: 358 | AJ13: 1 | AK13: =AI13*AA13*AJ13 -> 358 | AL13: Catalogo | AM13: 52-D1 | AN13: 0.96 | AO13: 52-D2 | AP13: 1 | AQ13: 52-E1 | AR13: 0.77 | AS13: 52-E2 | AT13: 1 | AU13: 52-E3 | AV13: 1 | AW13: 52-E4 | AX13: 1 | AY13: 52-E5 | AZ13: 1 | BA13: 52-E6 | BB13: 1 | BC13: =AK13*AN13*AP13*AR13*AT13*AV13*AX13*AZ13*BB13 -> 264.6336 | BD13: Disjuntor | BE13: EN60905 | BF13: 250 | BG13: 1.3 | BH13: 130 | BI13: OK | BJ13: OK | BK13: 0.0225 | BL13: 0.03625 | BM13: 0.0435 | BN13: 0.25928315 | BO13: 0 | BQ13: 1 | BR13: 0.6001556 | BS13: 0.0026093722 | BT13: 0.0026093722 | BU13: OK | BV13: (XV) - Rígido | BW13: #N/A | BX13: #N/A | BY13: #N/A | BZ13: #N/A
A14: QPV | B14: 500 | C14: QInterligação | D14: Trif. Equilibrado | F14: =VLOOKUP('Cálculos Elétricos'!D14,'Tabelas de apoio'!$H$20:$K$24,2,FALSE) -> 400 | G14: =B14*1100 -> 550000 | H14: 1 | I14: =DEGREES(ACOS(H14)) -> 0 | J14: =G14 -> 550000 | K14: =IF(D14="Monofásico",(J14)/(F14*H14),IF(F14=400,(J14)/(SQRT(3)*F14),IF(D14="DC",#REF!, "ERRO"))) -> 793.85662 | L14: 1 | M14: =L14*K14 -> 793.85662 | N14: Monocondutor | O14: LXV | P14: À vista | Q14: Caminhos de cabos, escadas e consolas | R14: =INDEX('Tabelas de apoio'!$I$9:$P$15,MATCH(P14,'Tabelas de apoio'!$H$9:$H$15,0),MATCH(Q14,'Tabelas de apoio'!$I$8:$P$8,0)) -> 12,13,13,15,16 | S14: 13 | T14: =VLOOKUP(S14,'Tabelas de apoio'!C8:D52,2) -> E ou F [4](3) | U14: F | V14: 140 | W14: =IF(V14<30,V14+V14*0.2,V14+V14*0.1) -> 154 | X14: =INDEX('Tabelas de apoio'!$I$27:$I$42,MATCH(O14,'Tabelas de apoio'!$H$27:$H$42,0)) -> AL | Y14: =LOOKUP(O14,'Tabelas de apoio'!$I$27:$I$42,'Tabelas de apoio'!$J$27:$J$42) -> XLPE | Z14: 240 | AA14: 3 | AB14: 185 | AC14: 2 | AD14: 185 | AE14: 2 | AF14: =IF(N14="Multicondutor",W14*AA14,3*W14*AA14) -> 1386 | AG14: =IF(N14="Multicondutor",0,AC14*W14) -> 308 | AH14: =IF(N14="Multicondutor",0,AE14*W14) -> 308 | AI14: 492 | AJ14: 1 | AK14: =AI14*AA14*AJ14 -> 1476 | AL14: Catalogo | AM14: 52-D1 | AN14: 0.96 | AO14: 52-D2 | AP14: 1 | AQ14: 52-E1 | AR14: 0.82 | AS14: 52-E2 | AT14: 1 | AU14: 52-E3 | AV14: 1 | AW14: 52-E4 | AX14: 1 | AY14: 52-E5 | AZ14: 1 | BA14: 52-E6 | BB14: 1 | BC14: =AK14*AN14*AP14*AR14*AT14*AV14*AX14*AZ14*BB14 -> 1161.9072 | BD14: Disjuntor | BE14: EN60898 | BF14: 850 | BG14: =IF(BD14="Disjuntor",IF(BE14="EN60898",1.45,1.3),IF(BD14="Fusível",IF(BF14>=16,1.6,IF(AND(BF14>4,BF14<16),1.9,2.1)),"Erro")) -> 1.45 | BH14: =BG14*BF14 -> 1232.5 | BI14: =IF(AND(M14<BF14,BF14<BC14),"OK","erro") -> OK | BJ14: =IF(BH14<(1.45*BC14),"OK","erro") -> OK | BK14: =IF(X14="Cobre",0.0225,IF(X14="Al",0.036,"Erro")) -> 0.036 | BL14: =$BL$5*1.25 -> 0.03625 | BM14: =$BL$5*1.5 -> 0.0435 | BN14: =VLOOKUP(Z14,$BK$41:$BV$59,9,TRUE) -> 0.23332473 | BO14: =SIN(RADIANS(I14)) -> 0 | BQ14: =IF(D14="Trif. Equilibrado",1,2) -> 1 | BR14: =BQ14*(BK14*(W14/Z14)*H14 + BN14*W14*BO14)*(M14/AA14) -> 6.112696 | BS14: =BR14/230 -> 0.026576939 | BT14: =BS14 -> 0.026576939 | BU14: =IF(BT14<$BU$7,"OK","ERRO") -> OK | BV14: RZ1K - Verde fléxivel | BW14: {=INDEX(Table1[],MATCH(1,(Z14=Table1[Cabo])*('Cálculos Elétricos'!X14=Table1[Material])*('Cálculos Elétricos'!BV14=Table1[Isolamento])*(N14=Table1[Mono/Multi]),0),5)*AF14} -> #N/A | BX14: {=INDEX(Table1[],MATCH(1,(AB14=Table1[Cabo])*('Cálculos Elétricos'!X14=Table1[Material])*('Cálculos Elétricos'!BV14=Table1[Isolamento])*(N14=Table1[Mono/Multi]),0),5)*AG14} -> #N/A | BY14: {=INDEX(Table1[],MATCH(1,(AD14=Table1[Cabo])*('Cálculos Elétricos'!X14=Table1[Material])*('Cálculos Elétricos'!BV14=Table1[Isolamento])*(N14=Table1[Mono/Multi]),0),5)*AH14} -> #N/A | BZ14: =BW14+BX14+BY14 -> #N/A
A15: QInterligação | B15: 500 | C15: Qentrada | D15: Trif. Equilibrado | F15: =VLOOKUP('Cálculos Elétricos'!D15,'Tabelas de apoio'!$H$20:$K$24,2,FALSE) -> 400 | G15: =B15*1100 -> 550000 | H15: 1 | I15: =DEGREES(ACOS(H15)) -> 0 | J15: =G15 -> 550000 | K15: =IF(D15="Monofásico",(J15)/(F15*H15),IF(F15=400,(J15)/(SQRT(3)*F15),IF(D15="DC",#REF!, "ERRO"))) -> 793.85662 | L15: 1 | M15: =L15*K15 -> 793.85662 | N15: Monocondutor | O15: XV | P15: À vista | Q15: Caminhos de cabos, escadas e consolas | R15: =INDEX('Tabelas de apoio'!$I$9:$P$15,MATCH(P15,'Tabelas de apoio'!$H$9:$H$15,0),MATCH(Q15,'Tabelas de apoio'!$I$8:$P$8,0)) -> 12,13,13,15,16 | S15: 13 | T15: =VLOOKUP(S15,'Tabelas de apoio'!C9:D53,2) -> E ou F [4](3) | U15: F | V15: 7 | W15: =IF(V15<30,V15+V15*0.2,V15+V15*0.1) -> 8.4 | X15: =INDEX('Tabelas de apoio'!$I$27:$I$42,MATCH(O15,'Tabelas de apoio'!$H$27:$H$42,0)) -> Cobre | Y15: =LOOKUP(O15,'Tabelas de apoio'!$I$27:$I$42,'Tabelas de apoio'!$J$27:$J$42) -> XLPE | Z15: 185 | AA15: 2 | AB15: 185 | AC15: 1 | AD15: 185 | AE15: 1 | AF15: =IF(N15="Multicondutor",W15*AA15,3*W15*AA15) -> 50.4 | AG15: =IF(N15="Multicondutor",0,AC15*W15) -> 8.4 | AH15: =IF(N15="Multicondutor",0,AE15*W15) -> 8.4 | AI15: 533 | AJ15: 1 | AK15: =AI15*AA15*AJ15 -> 1066 | AL15: Catalogo | AM15: 52-D1 | AN15: 0.96 | AO15: 52-D2 | AP15: 1 | AQ15: 52-E1 | AR15: 0.88 | AS15: 52-E2 | AT15: 1 | AU15: 52-E3 | AV15: 1 | AW15: 52-E4 | AX15: 1 | AY15: 52-E5 | AZ15: 1 | BA15: 52-E6 | BB15: 1 | BC15: =AK15*AN15*AP15*AR15*AT15*AV15*AX15*AZ15*BB15 -> 900.5568 | BD15: Disjuntor | BE15: EN60898 | BF15: 850 | BG15: =IF(BD15="Disjuntor",IF(BE15="EN60898",1.45,1.3),IF(BD15="Fusível",IF(BF15>=16,1.6,IF(AND(BF15>4,BF15<16),1.9,2.1)),"Erro")) -> 1.45 | BH15: =BG15*BF15 -> 1232.5 | BI15: =IF(AND(M15<BF15,BF15<BC15),"OK","erro") -> OK | BJ15: =IF(BH15<(1.45*BC15),"OK","erro") -> OK | BK15: =IF(X15="Cobre",0.0225,IF(X15="Al",0.036,"Erro")) -> 0.0225 | BL15: =$BL$5*1.25 -> 0.03625 | BM15: =$BL$5*1.5 -> 0.0435 | BN15: =VLOOKUP(Z15,$BK$41:$BV$59,9,TRUE) -> 0.2347436 | BO15: =SIN(RADIANS(I15)) -> 0 | BQ15: =IF(D15="Trif. Equilibrado",1,2) -> 1 | BR15: =BQ15*(BK15*(W15/Z15)*H15 + BN15*W15*BO15)*(M15/AA15) -> 0.40551054 | BS15: =BR15/230 -> 0.0017630893 | BT15: =BS15 -> 0.0017630893 | BU15: =IF(BT15<$BU$7,"OK","ERRO") -> OK | BV15: RZ1K - Verde fléxivel | BW15: {=INDEX(Table1[],MATCH(1,(Z15=Table1[Cabo])*('Cálculos Elétricos'!X15=Table1[Material])*('Cálculos Elétricos'!BV15=Table1[Isolamento])*(N15=Table1[Mono/Multi]),0),5)*AF15} -> #N/A | BX15: {=INDEX(Table1[],MATCH(1,(AB15=Table1[Cabo])*('Cálculos Elétricos'!X15=Table1[Material])*('Cálculos Elétricos'!BV15=Table1[Isolamento])*(N15=Table1[Mono/Multi]),0),5)*AG15} -> #N/A | BY15: {=INDEX(Table1[],MATCH(1,(AD15=Table1[Cabo])*('Cálculos Elétricos'!X15=Table1[Material])*('Cálculos Elétricos'!BV15=Table1[Isolamento])*(N15=Table1[Mono/Multi]),0),5)*AH15} -> #N/A | BZ15: =SUM(BZ14:BZ14) -> #N/A
AB23: =240*3 -> 720
AB24: =AB23/2 -> 360
AB25: =AB24/2 -> 180
BK40: Secção Nominal (mm2) | BN40: Diâmetro da alma, d (mm) | BO40: Espessura do Isola. cobre | BP40: Espessura do Isola. alumínio | BQ40: Distância entre eixos cobre, am (mm) | BR40: Distância entre eixos alumínio, am (mm) | BS40: l (mH/km) | BU40: X (Ω/m)
BS41: Cobre | BT41: Alumínio | BU41: Cobre | BV41: Alumínio
BK42: 1.5 | BN42: =2*SQRT(BK42/PI()) -> 1.3819766 | BO42: 0.7 | BP42: - | BQ42: =BN42+2*BO42 -> 2.7819766 | BR42: - | BS42: =0.05+0.46*LOG(2*BQ42/BN42) -> 0.32824608 | BT42: - | BU42: =2*PI()*50*BS42*10^-3/1000 -> 0.00010312155 | BV42: -
BK43: 2.5 | BN43: =2*SQRT(BK43/PI()) -> 1.7841241 | BO43: 0.8 | BP43: - | BQ43: =BN43+2*BO43 -> 3.3841241 | BR43: - | BS43: =0.05+0.46*LOG(2*BQ43/BN43) -> 0.31636356 | BT43: - | BU43: =2*PI()*50*BS43*10^-3/1000 -> 9.9388543e-05 | BV43: -
BK44: 4 | BN44: =2*SQRT(BK44/PI()) -> 2.2567583 | BO44: 0.8 | BP44: - | BQ44: =BN44+2*BO44 -> 3.8567583 | BR44: - | BS44: =0.05+0.46*LOG(2*BQ44/BN44) -> 0.29553299 | BT44: - | BU44: =2*PI()*50*BS44*10^-3/1000 -> 9.2844427e-05 | BV44: -
BK45: 6 | BN45: =2*SQRT(BK45/PI()) -> 2.7639532 | BO45: 0.8 | BP45: - | BQ45: =BN45+2*BO45 -> 4.3639532 | BR45: - | BS45: =0.05+0.46*LOG(2*BQ45/BN45) -> 0.27971452 | BT45: - | BU45: =2*PI()*50*BS45*10^-3/1000 -> 8.7874909e-05 | BV45: -
BK46: 10 | BN46: =2*SQRT(BK46/PI()) -> 3.5682482 | BO46: 1 | BP46: - | BQ46: =BN46+2*BO46 -> 5.5682482 | BR46: - | BS46: =0.05+0.46*LOG(2*BQ46/BN46) -> 0.27737502 | BT46: - | BU46: =2*PI()*50*BS46*10^-3/1000 -> 8.7139933e-05 | BV46: -
BK47: 16 | BN47: =2*SQRT(BK47/PI()) -> 4.5135167 | BO47: 1 | BP47: 1 | BQ47: =BN47+2*BO47 -> 6.5135167 | BR47: =BN47+2*BP47 -> 6.5135167 | BS47: =0.05+0.46*LOG(2*BQ47/BN47) -> 0.26175202 | BT47: =0.05+0.46*LOG(2*BR47/BN47) -> 0.26175202 | BU47: =2*PI()*50*BS47*10^-3/1000 -> 8.2231822e-05 | BV47: =2*PI()*50*BT47*10^-3/1000 -> 8.2231822e-05
BK48: 25 | BN48: =2*SQRT(BK48/PI()) -> 5.6418958 | BO48: 1.2 | BP48: 1.2 | BQ48: =BN48+2*BO48 -> 8.0418958 | BR48: =BN48+2*BP48 -> 8.0418958 | BS48: =0.05+0.46*LOG(2*BQ48/BN48) -> 0.25928315 | BT48: =0.05+0.46*LOG(2*BR48/BN48) -> 0.25928315 | BU48: =2*PI()*50*BS48*10^-3/1000 -> 8.1456205e-05 | BV48: =2*PI()*50*BT48*10^-3/1000 -> 8.1456205e-05
BK49: 35 | BN49: =2*SQRT(BK49/PI()) -> 6.6755812 | BO49: 1.2 | BP49: 1.2 | BQ49: =BN49+2*BO49 -> 9.0755812 | BR49: =BN49+2*BP49 -> 9.0755812 | BS49: =0.05+0.46*LOG(2*BQ49/BN49) -> 0.24983107 | BT49: =0.05+0.46*LOG(2*BR49/BN49) -> 0.24983107 | BU49: =2*PI()*50*BS49*10^-3/1000 -> 7.8486744e-05 | BV49: =2*PI()*50*BT49*10^-3/1000 -> 7.8486744e-05
BK50: 50 | BN50: =2*SQRT(BK50/PI()) -> 7.9788456 | BO50: 1.4 | BP50: 1.4 | BQ50: =BN50+2*BO50 -> 10.778846 | BR50: =BN50+2*BP50 -> 10.778846 | BS50: =0.05+0.46*LOG(2*BQ50/BN50) -> 0.24856461 | BT50: =0.05+0.46*LOG(2*BR50/BN50) -> 0.24856461 | BU50: =2*PI()*50*BS50*10^-3/1000 -> 7.8088874e-05 | BV50: =2*PI()*50*BT50*10^-3/1000 -> 7.8088874e-05
BK51: 70 | BN51: =2*SQRT(BK51/PI()) -> 9.4406974 | BO51: 1.4 | BP51: 1.4 | BQ51: =BN51+2*BO51 -> 12.240697 | BR51: =BN51+2*BP51 -> 12.240697 | BS51: =0.05+0.46*LOG(2*BQ51/BN51) -> 0.24036276 | BT51: =0.05+0.46*LOG(2*BR51/BN51) -> 0.24036276 | BU51: =2*PI()*50*BS51*10^-3/1000 -> 7.5512187e-05 | BV51: =2*PI()*50*BT51*10^-3/1000 -> 7.5512187e-05
BK52: 95 | BN52: =2*SQRT(BK52/PI()) -> 10.99808 | BO52: 1.6 | BP52: 1.4 | BQ52: =BN52+2*BO52 -> 14.19808 | BR52: =BN52+2*BP52 -> 13.79808 | BS52: =0.05+0.46*LOG(2*BQ52/BN52) -> 0.23949366 | BT52: =0.05+0.46*LOG(2*BR52/BN52) -> 0.23378462 | BU52: =2*PI()*50*BS52*10^-3/1000 -> 7.5239153e-05 | BV52: =2*PI()*50*BT52*10^-3/1000 -> 7.3445604e-05
BK53: 120 | BN53: =2*SQRT(BK53/PI()) -> 12.360774 | BO53: 1.6 | BP53: 1.6 | BQ53: =BN53+2*BO53 -> 15.560774 | BR53: =BN53+2*BP53 -> 15.560774 | BS53: =0.05+0.46*LOG(2*BQ53/BN53) -> 0.23446714 | BT53: =0.05+0.46*LOG(2*BR53/BN53) -> 0.23446714 | BU53: =2*PI()*50*BS53*10^-3/1000 -> 7.3660024e-05 | BV53: =2*PI()*50*BT53*10^-3/1000 -> 7.3660024e-05
BK54: 150 | BN54: =2*SQRT(BK54/PI()) -> 13.819766 | BO54: 1.8 | BP54: 1.8 | BQ54: =BN54+2*BO54 -> 17.419766 | BR54: =BN54+2*BP54 -> 17.419766 | BS54: =0.05+0.46*LOG(2*BQ54/BN54) -> 0.23472295 | BT54: =0.05+0.46*LOG(2*BR54/BN54) -> 0.23472295 | BU54: =2*PI()*50*BS54*10^-3/1000 -> 7.3740388e-05 | BV54: =2*PI()*50*BT54*10^-3/1000 -> 7.3740388e-05
BK55: 185 | BN55: =2*SQRT(BK55/PI()) -> 15.347616 | BO55: 2 | BP55: 2 | BQ55: =BN55+2*BO55 -> 19.347616 | BR55: =BN55+2*BP55 -> 19.347616 | BS55: =0.05+0.46*LOG(2*BQ55/BN55) -> 0.2347436 | BT55: =0.05+0.46*LOG(2*BR55/BN55) -> 0.2347436 | BU55: =2*PI()*50*BS55*10^-3/1000 -> 7.3746878e-05 | BV55: =2*PI()*50*BT55*10^-3/1000 -> 7.3746878e-05
BK56: 240 | BN56: =2*SQRT(BK56/PI()) -> 17.480775 | BO56: 2.2 | BP56: 2.2 | BQ56: =BN56+2*BO56 -> 21.880775 | BR56: =BN56+2*BP56 -> 21.880775 | BS56: =0.05+0.46*LOG(2*BQ56/BN56) -> 0.23332473 | BT56: =0.05+0.46*LOG(2*BR56/BN56) -> 0.23332473 | BU56: =2*PI()*50*BS56*10^-3/1000 -> 7.3301125e-05 | BV56: =2*PI()*50*BT56*10^-3/1000 -> 7.3301125e-05
BK57: 300 | BN57: =2*SQRT(BK57/PI()) -> 19.5441 | BO57: 2.4 | BP57: 2.4 | BQ57: =BN57+2*BO57 -> 24.3441 | BR57: =BN57+2*BP57 -> 24.3441 | BS57: =0.05+0.46*LOG(2*BQ57/BN57) -> 0.2323477 | BT57: =0.05+0.46*LOG(2*BR57/BN57) -> 0.2323477 | BU57: =2*PI()*50*BS57*10^-3/1000 -> 7.2994182e-05 | BV57: =2*PI()*50*BT57*10^-3/1000 -> 7.2994182e-05
BK58: 400 | BN58: =2*SQRT(BK58/PI()) -> 22.567583 | BO58: 2.6 | BP58: 2.6 | BQ58: =BN58+2*BO58 -> 27.767583 | BR58: =BN58+2*BP58 -> 27.767583 | BS58: =0.05+0.46*LOG(2*BQ58/BN58) -> 0.22989819 | BT58: =0.05+0.46*LOG(2*BR58/BN58) -> 0.22989819 | BU58: =2*PI()*50*BS58*10^-3/1000 -> 7.2224647e-05 | BV58: =2*PI()*50*BT58*10^-3/1000 -> 7.2224647e-05
BK59: 500 | BN59: =2*SQRT(BK59/PI()) -> 25.231325 | BO59: - | BP59: 2.8 | BQ59: - | BR59: =BN59+2*BP59 -> 30.831325 | BS59: - | BT59: =0.05+0.46*LOG(2*BR59/BN59) -> 0.22851778 | BU59: - | BV59: =2*PI()*50*BT59*10^-3/1000 -> 7.1790977e-05
BK60: 630 | BN60: =2*SQRT(BK60/PI()) -> 28.322092 | BO60: - | BP60: 2.8 | BQ60: - | BR60: =BN60+2*BP60 -> 33.922092 | BS60: - | BT60: =0.05+0.46*LOG(2*BR60/BN60) -> 0.22451815 | BU60: - | BV60: =2*PI()*50*BT60*10^-3/1000 -> 7.0534459e-05

Sheet F.C
B66: Refª
B69: 1
B72: 2
B74: 3
B76: 4
B78: 5
L82: Temos de considerar o número de circuitos. 3 cabos por fase equivalem a 1 circuito.

Sheet Tabelas de apoio
A1: (2) - Podem ser utilizados outros tipos de canalizações não indicados nesta secção, desde que sejam cumpridas as regras gerais indicadas na presente parte das Regras Técnicas.
A2: Quadro 52H
A3: Exemplos de modos de instalação
A4: Exemplo | B4: Designação | C4: Refª | D4: Método de refª(1)
B6: Condutores isolados em condutas circulares (tubos) embebidas em elementos da construção, termicamente isolantes | C6: 1 | D6: A | H6: Instalação das Canalizações | T6: Disjuntores
B7: Cabos multicondutores em condutas circulares (tubos) embebidas em elementos da construção, termicamente isolantes | C7: 2 | D7: A2 | H7: Situação | I7: Modos de instalação | T7: In | U7: Inf | V7: If
B8: Condutores isolados em condutas circulares (tubos) montadas à vista | C8: 3 | D8: B | I8: Sem fixação | J8: Fixação directa | K8: Condutas circulares (tubos) | L8: Calhas | M8: Condutas não circulares | N8: Caminhos de cabos, escadas e consolas | O8: Sobre isoladores | P8: Cabos auto-suportados | T8: (A) | U8: (A) | V8: (A)
B9: Cabos mono ou multicondutores em condutas circulares (tubos) montadas à vista | C9: 3A | D9: (em estudo) | H9: Ocos de construção | I9: 21,25,73,74 | J9: 0 | K9: 22,73,74 | L9: - | M9: 23 | N9: 12,13,13,15,16 | O9: - | P9: - | T9: 2
B10: Condutores isolados em condutas não circulares montadas à vista. | C10: 4 | D10: B2 | H10: Caleiras | I10: 43 | J10: 43 | K10: 41.42 | L10: 31.32 | M10: 4.24 | N10: 12,13,13,15,16 | O10: - | P10: - | T10: 4
B11: Cabos mono ou multicondutores em condutas não circulares montadas à vista | C11: 4A | D11: (em estudo) | H11: Enterradas | I11: 62.63 | J11: 0 | K11: 61 | L11: - | M11: 61 | N11: 0 | O11: - | P11: - | T11: 6 | U11: 6.3 | V11: 8.1
B12: Condutores isolados em condutas circulares (tubos) embebidas nos elementos da construção, em alvenaria | C12: 5 | D12: B | H12: Embebidas | I12: 52.53 | J12: 51 | K12: 1,2,5 | L12: 33 | M12: 24 | N12: 0 | O12: - | P12: - | T12: 8 | U12: 8.4 | V12: 10.8
B13: Cabos mono ou multicondutores em condutas circulares (tubos) embebidas nos elementos da construção, em alvenaria | C13: 5A | D13: (em estudo) | H13: À vista | I13: - | J13: 11 | K13: 3 | L13: 31,32,71,72 | M13: 4 | N13: 12,13,13,15,16 | O13: 18 | P13: - | T13: 10 | U13: 10.5 | V13: 13.5
B14: Cabos mono ou multicondutores (com ou sem armadura) fixados às paredes | C14: 11 | D14: C | H14: Linhas aérias | I14: - | J14: - | K14: 0 | L14: 34 | M14: - | N14: 12,13,13,15,16 | O14: 18 | P14: 17 | T14: 12 | U14: 12.6 | V14: 16.2
B15: Cabos mono ou multicondutores (com ou sem armadura) fixados aos tectos | C15: 11A | D15: C [3] | H15: Imersas | I15: 81 | J15: 81 | K15: 0 | L15: - | M15: 0 | N15: 0 | O15: - | P15: - | T15: 16 | U15: 16.8 | V15: 21.6
B16: Cabos mono ou multicondutores (com ou sem armadura) em caminhos de cabos não perfurados | C16: 12 | D16: C [2](3) | T16: 20 | U16: 21 | V16: 27
B17: Cabos mono ou multicondutores (com ou sem armadura) em caminhos de cabos perfurados | C17: 13 | D17: E ou F [4](3) | T17: 25 | U17: 26.3 | V17: 33.8
B18: Cabos mono ou multicondutores (com ou sem armadura) em consolas | C18: 14 | D18: E ou F [4] ou [5](2)(3) G | H18: Tensões | M18: Tipo de cabo | T18: 32 | U18: 33.6 | V18: 43.2
B19: Cabos mono ou multicondutores (com ou sem armadura) fixados por braçadeiras e afastados dos elementos da construção | C19: 15 | D19: E ou F [4] ou [5](2)(3) G | H19: Tipo de Circuito | I19: Uo | J19: U | K19: b | M19: Monocondutor | T19: 40 | U19: 42 | V19: 54
B20: Cabos mono ou multicondutores (com ou sem armadura) em escadas (para cabos) | C20: 16 | D20: E ou F [4] ou [5](2)(3) G | H20: Monofásico | I20: 230 | K20: 2 | M20: Multicondutor | T20: 50 | U20: 53 | V20: 68
B21: Cabos mono ou multicondutores auto- suportados ou suspensos por fiadores | C21: 17 | D21: E ou G | H21: Bifásico | I21: 400 | J21: 400 | K21: 2 | T21: 63 | U21: 66 | V21: 85
B22: Condutores nus ou isolados assentes sobre isoladores | C22: 18 | D22: G | H22: Trif. c/ neutro | I22: 230 | J22: 400 | K22: 2 | T22: 80 | U22: 84 | V22: 108
B23: Cabos mono ou multicondutores em ocos da construção | C23: 21 | D23: B2 para: 1,5De V 5De B para: 5De V 50De (4) | H23: Trif. Equilibrado | I23: 400 | J23: 400 | K23: 1 | T23: 85 | U23: 84 | V23: 108
B24: Condutores isolados em condutas circulares (tubos) em ocos da construção | C24: 22 | D24: B2 para: 1,5De V 20De B para: 20De V 50De (4) | H24: DC | T24: 100 | U24: 105 | V24: 135
B25: Cabos mono ou multicondutores em condutas circulares (tubos) em ocos da construção | C25: 22A | D25: (em estudo) | T25: 112 | U25: 105 | V25: 135
B26: Condutores isolados em condutas não circulares em ocos da construção | C26: 23 | D26: B2 para: 1,5De V 20De B para: 20De V 50De (4) | H26: Cabo | I26: Alma | J26: Isolamento | T26: 125 | U26: 131 | V26: 169
B27: Cabos mono ou multicondutores em condutas não circulares em ocos da construção | C27: 23A | D27: (em estudo) | H27: H07V-U | I27: Cobre | J27: PVC | T27: 128
B28: Condutores isolados em condutas não circulares embebidas durante a construção do edifício | C28: 24 | D28: B2 para: 1,5De V 5De B para: 5De V 50De (4) | H28: H07V-R | I28: Cobre | J28: PVC | T28: 160 | U28: 168 | V28: 216
B29: Cabos mono ou multicondutores em condutas não circulares embebidas durante a construção do edifício | C29: 24A | D29: (em estudo) | H29: H07V-K | I29: Cobre | J29: PVC | T29: 200 | U29: 210 | V29: 270
B30: Cabos mono ou multicondutores em tectos falsos ou suspensos | C30: 25 | D30: B2 para: 1,5De V 5De B para: 5De V 50De (4) | H30: H05VV-F | I30: Cobre | J30: PVC | T30: 250 | U30: 263 | V30: 338
B31: Condutores isolados ou cabos mono ou multicondutores em calhas fixadas a elementos da construção em percursos horizontais | C31: 31 | D31: B(5)(8) | H31: PT-N05VV-U | I31: Cobre | J31: PVC | T31: 315 | U31: 331 | V31: 425
B32: Condutores isolados ou cabos mono ou multicondutores em calhas fixadas a elementos da construção em percursos verticais | C32: 32 | D32: B(5)(8) | H32: XG (RF) | I32: Cobre | J32: XLPE | T32: 400 | U32: 420 | V32: 540
B33: Condutores isolados em calhas embebidas nos pavimentos e nas paredes | C33: 33 | D33: B(5) | H33: NHXH (FE180)E90 | I33: Cobre | J33: XLPE | T33: 500 | U33: 525 | V33: 675
B34: Cabos mono ou multicondutores em calhas embebidas nos pavimentos e nas paredes | C34: 33A | D34: B2 | H34: XZ1 | I34: Cobre | J34: XLPE | T34: 630 | U34: 662 | V34: 851
B35: Condutores isolados em calhas suspensas | C35: 34 | D35: B(5) B2 | H35: XG (ZH) | I35: Cobre | J35: XLPE | T35: 652 | U35: 662 | V35: 851
B36: Cabos mono ou multicondutores em calhas suspensas | C36: 34A | H36: XV | I36: Cobre | J36: XLPE | T36: 760 | U36: 662 | V36: 851
T37: 800 | U37: 840 | V37: 1080
B38: Condutores isolados em condutas circulares (tubos) ou cabos multicondutores em caleiras fechadas, em percursos horizontais ou verticais | C38: 41 | D38: B2 para: 1,5De V 20De B para: 20De V 50De (4) | H38: XV - K | I38: Cobre | J38: XLPE | T38: 850 | U38: 840 | V38: 1080
B39: Condutores isolados em condutas circulares (tubos) em caleiras ventiladas | C39: 42 | D39: B(6)(8) | H39: LXV | I39: AL | J39: XLPE | T39: 1000 | U39: 1050 | V39: 1350
B40: Cabos mono ou multicondutores em caleiras abertas ou ventiladas | C40: 43 | D40: B(6) | H40: LXHIOV | I40: AL | J40: XLPE | T40: 1250 | U40: 1313 | V40: 1688
B41: Cabos multicondutores embebidos directamente em elementos da construção, termicamente isolantes | C41: 51 | D41: A | H41: LSXV | I41: AL | J41: XLPE | T41: 2000 | U41: 2100 | V41: 2700
...

Sheet CABOS
N1: Cabo | O1: Material | P1: Isolamento | Q1: Mono/Multi | R1: Preço € | S1: Isolamento | T1: Monocondutor | U1: Multicondutor
E2: [E] QUADRO 52-C1 | N2: 16 | O2: AL | P2: LXV | Q2: Monocondutor | R2: 0.788 | S2: LXV | T2: 120 | U2: 10
E3: Correntes admissíveis, em amperes, para os métodos de referência A, B e C (de acordo com o quadro 52H) | N3: 25 | O3: AL | P3: LXV | Q3: Monocondutor | R3: 1.105 | S3: RZ1K - Verde fléxivel | T3: 150 | U3: 16
N4: 35 | O4: AL | P4: LXV | Q4: Monocondutor | R4: 1.435 | S4: (XV) - Rígido | T4: 16 | U4: 25
E5: Condutores isolados a policloreto de vinilo (PVC), para: | N5: 50 | O5: AL | P5: LXV | Q5: Monocondutor | R5: 1.801 | S5: (XZ1) - Condições especiais contra fogos | T5: 185 | U5: 35
E6: dois condutores carregados | N6: 70 | O6: AL | P6: LXV | Q6: Monocondutor | R6: 2.491 | T6: 240
E7: cobre ou alumínio | N7: 95 | O7: AL | P7: LXV | Q7: Monocondutor | R7: 3.338 | T7: 25
E8: temperatura da alma condutora: 70°C | N8: 120 | O8: AL | P8: LXV | Q8: Monocondutor | R8: 3.994 | T8: 300
E9: temperatura ambiente: 30°C | N9: 150 | O9: AL | P9: LXV | Q9: Monocondutor | R9: 4.968 | T9: 35
N10: 185 | O10: AL | P10: LXV | Q10: Monocondutor | R10: 6.409
N11: 240 | O11: AL | P11: LXV | Q11: Monocondutor | R11: 7.783 | T11: 50
N12: 300 | O12: AL | P12: LXV | Q12: Monocondutor | R12: 9.814
E13: Secção nominal | F13: Método de referência | N13: 10 | O13: Cobre | P13: RZ1K - Verde fléxivel | Q13: Multicondutor | R13: 5.9 | T13: 70
E14: dos condutores | N14: 16 | O14: Cobre | P14: (XV) - Rígido | Q14: Multicondutor | R14: 18.16 | T14: 95
E15: (mm2) | F15: A | G15: B | H15: C(*) | N15: 16 | O15: Cobre | P15: RZ1K - Verde fléxivel | Q15: Multicondutor | R15: 10.67
E16: Condutores de cobre | N16: 16 | O16: Cobre | P16: (XZ1) - Condições especiais contra fogos | Q16: Multicondutor | R16: 20.163
E17: 1,5 | F17: 14,5 | G17: 17,5 | H17: 19,5 | N17: 16 | O17: Cobre | P17: (RVK - FXV) - Fléxivel | Q17: Multicondutor | R17: 10.35
E18: 2,5 | F18: 19,5 | G18: 24 | H18: 27 | N18: 25 | O18: Cobre | P18: (XZ1) - Condições especiais contra fogos | Q18: Multicondutor | R18: 31.413
E19: 4 | F19: 26 | G19: 32 | H19: 36 | N19: 25 | O19: Cobre | P19: RZ1K - Verde fléxivel | Q19: Multicondutor | R19: 14.3
E20: 6 | F20: 34 | G20: 41 | H20: 46 | N20: 25 | O20: Cobre | P20: (XV) - Rígido | Q20: Multicondutor | R20: 16.95
E21: 10 | F21: 46 | G21: 57 | H21: 63 | N21: 35 | O21: Cobre | P21: RZ1K - Verde fléxivel | Q21: Monocondutor | R21: =8.414*0.55 -> 4.6277
E22: 16 | F22: 61 | G22: 76 | H22: 85 | N22: 35 | O22: Cobre | P22: (XZ1) - Condições especiais contra fogos | Q22: Multicondutor | R22: 43.635
E23: 25 | F23: 80 | G23: 101 | H23: 112 | N23: 35 | O23: Cobre | P23: (RVK - FXV) - Fléxivel | Q23: Multicondutor | R23: 21.06
N24: 50 | O24: Cobre | P24: RZ1K - Verde fléxivel | Q24: Monocondutor | R24: 5.6
E25: 35 | F25: 99 | G25: 125 | H25: 138 | N25: 70 | O25: Cobre | P25: RZ1K - Verde fléxivel | Q25: Monocondutor | R25: =15.986*0.55 -> 8.7923
E26: 50 | F26: 119 | G26: 151 | H26: 168 | N26: 185 | O26: Cobre | P26: (XZ1) - Condições especiais contra fogos | Q26: Monocondutor | R26: 41.679
E27: 70 | F27: 151 | G27: 192 | H27: 213
E28: 95 | F28: 182 | G28: 232 | H28: 258 | M28: Novos preços | N28: 10 | O28: Cobre | P28: ENERGY CLASS RV/XV ECA 1KV 5G10 | Q28: Multicondutor | R28: =(8516.28/1000)*0.62 -> 5.2800936
E29: 120 | F29: 210 | G29: 269 | H29: 299 | N29: 16 | O29: Cobre | P29: ENERGY CLASS RV/XV ECA 1KV 5G16 | Q29: Multicondutor | R29: =(13195.74/1000)*0.62 -> 8.1813588
E30: 150 | F30: 240 | G30: - | H30: 344 | N30: 25 | O30: Cobre | P30: ENERGY CLASS RV/XV ECA 1KV 5G25 | Q30: Multicondutor | R30: =(21419.17/1000)*0.62 -> 13.279885
E31: 185 | F31: 273 | G31: - | H31: 392 | N31: 35 | O31: Cobre | P31: ENERGY CLASS RV/XV ECA 1KV 5G35 | Q31: Multicondutor | R31: =(29788.06/1000)*0.62 -> 18.468597
E32: 240 | F32: 320 | G32: - | H32: 461 | N32: 35 | O32: Cobre | P32: ENERGY CLASS RV/XV ECA 1KV 1X35 | Q32: Monocondutor | R32: =(5798.29/1000)*0.62 -> 3.5949398
E33: 300 | F33: 367 | G33: - | H33: 530 | N33: 50 | O33: Cobre | P33: ENERGY CLASS RV/XV ECA 1KV 1X50 | Q33: Monocondutor | R33: =(7828.67/1000)*0.62 -> 4.8537754
E34: Condutores de Alumínio | N34: 35 | O34: Alumínio | P34: XZ1-AL (S) ECA 1KV AC-1,5KV DC 1X35 | Q34: Monocondutor | R34: =(1050.15/1000)*0.62 -> 0.651093
E35: 2,5 | F35: 15 | G35: 18.5 | H35: 21 | N35: 50 | O35: Alumínio | P35: XZ1-AL (S) ECA 1KV AC-1,5KV DC 1X50 | Q35: Monocondutor | R35: =(1282.08/1000)*0.62 -> 0.7948896
E36: 4 | F36: 20 | G36: 25 | H36: 26 | N36: 70 | O36: Alumínio | P36: XZ1-AL (S) ECA 1KV AC-1,5KV DC 1X70 | Q36: Monocondutor | R36: =(1777.08/1000)*0.62 -> 1.1017896
E37: 6 | F37: 26 | G37: 32 | H37: 36 | N37: 95 | O37: Alumínio | P37: XZ1-AL (S) ECA 1KV AC-1,5KV DC 1X95 | Q37: Monocondutor | R37: =(2348.83/1000)*0.62 -> 1.4562746
E38: 10 | F38: 36 | G38: 44 | H38: 49 | N38: 120 | O38: Alumínio | P38: XZ1-AL (S) ECA 1KV AC-1,5KV DC 1X120 | Q38: Monocondutor | R38: =(2919.23/1000)*0.62 -> 1.8099226
E39: 16 | F39: 48 | G39: 60 | H39: 66 | N39: 150 | O39: Alumínio | P39: XZ1-AL (S) ECA 1KV AC-1,5KV DC 1X150 | Q39: Monocondutor | R39: =(3564.61/1000)*0.62 -> 2.2100582
E40: 25 | F40: 63 | G40: 79 | H40: 83 | N40: 185 | O40: Alumínio | P40: XZ1-AL (S) ECA 1KV AC-1,5KV DC 1X185 | Q40: Monocondutor | R40: =(4468.25/1000)*0.62 -> 2.770315
...

Sheet Paineís (Não Alterar)
A1: Marca | B1: Risen | I1: ZNShine | M1: QCELLS | X1: Marcas | Z1: Modelos Risen | AB1: Modelos ZNShine | AD1: Modelos JA Solar | AF1: ModelosQCell
A2: Modelo | B2: RSM 130-8-440M | C2: RSM144-9-545M | D2: RSM144-9-575BNDG | E2: RSM144-9-565BNDG-585BNDG | F2: RSM144-9-570-595BNDG | G2: RSM144-10-600BNDG | H2: RSM132-11-610-635BNDG | I2: ZMX7-GPLD144-590 W | J2: ZXM7-EHLD144 | K2: ZXM7-UHLD144 | L2: ZXN7-MD144 600 | M2: Q.PEAK DUO ML-611 | X2: Risen | Z2: RSM 130-8-440M | AB2: ZXM7-EHLD144 | AF2: Q.PEAK DUO ML-611
A3: Potência Pico (Wp) | B3: 440 | C3: 545 | D3: 575 | E3: 585 | F3: 590 | G3: 600 | H3: 620 | I3: 590 | J3: 550 | K3: 570 | L3: 600 | M3: 490W | X3: JASolar | Z3: RSM144-9-545M | AB3: ZXM7-UHLD144
A4: Nº de células | B4: 130 | C4: 144 | E4: 144 | F4: 144 | G4: 144 | H4: 132 | I4: 144 | J4: 144 | K4: 144 | L4: 144 | M4: 132 | X4: ZNShine | Z4: RSM144-9-575BNDG | AB4: ZMX7-SHLD120
A5: Tensão nominal (V) | B5: 37.34 | C5: 42.11 | D5: 43.6 | E5: 44 | F5: 44.16 | G5: 43.25 | H5: 40.81 | I5: 43.2 | J5: 41.8 | K5: 42.4 | L5: 43.6 | M5: 28.02 | X5: QCELLS | Z5: RSM144-10-600BNDG
A6: Corrente nominal (A) | B6: 11.79 | C6: 12.96 | D6: 13.21 | E6: 13.32 | F6: 13.38 | G6: 13.89 | H6: 16.65 | I6: 13.66 | J6: 13.16 | K6: 13.45 | L6: 13.77 | M6: 12.95
A7: Tensão circuito aberto (V) | B7: 44.85 | C7: 49.7 | D7: 51.97 | E7: 52.37 | F7: 52.55 | G7: 52.05 | H7: 48.89 | I7: 51.8 | J7: 50.1 | K7: 51 | L7: 52.2 | M7: 45.67
A8: Corrente curto-circuito (A) | B8: 12.5 | C8: 13.84 | D8: 14.06 | E8: 14.18 | F8: 14.24 | G8: 14.66 | H8: 17.58 | I8: 14.42 | J8: 13.9 | K8: 14.18 | L8: 14.54 | M8: 13.6
A9: Coeficiente de temperatura para Voc (%/°C) | B9: -0.25 | C9: -0.275 | D9: -0.25 | E9: -0.25 | F9: -0.25 | G9: -0.25 | H9: -0.25 | I9: -0.25 | J9: -0.29 | K9: -0.25 | L9: -0.25 | M9: -0.27
A10: Coeficiente de temperatura para Isc (%/°C) | B10: 0.04 | C10: 0.045 | D10: 0.046 | E10: 0.046 | F10: 0.046 | G10: 0.046 | H10: 0.046 | I10: 0.046 | J10: 0.05 | K10: 0.046 | L10: 0.046 | M10: 0.04
A11: Coeficiente de temperatura para Pmpp (%/°C) | B11: -0.34 | C11: -0.35 | D11: -0.29 | E11: -0.29 | F11: -0.29 | G11: -0.29 | H11: -0.29 | I11: 0.3 | J11: -0.29 | K11: -0.3 | L11: -0.3 | M11: -0.34
A12: Temperatura mínima no local (°C) | B12: -10 | C12: -10 | D12: -40 | E12: -40 | F12: -40 | G12: -40 | H12: -40 | I12: -40 | J12: -10 | K12: -10 | L12: -10 | M12: -40
A13: Eficiência Máxima | B13: 21.2 | C13: 21.1 | D13: 22.6 | E13: 22.7 | F13: 22.8 | G13: 23.5 | H13: 22.8 | I13: 23.02 | J13: 21.28 | K13: 22.06 | L13: 23.42 | M13: 21.5
A14: Eficiência aos 25 anos | B14: 84.8 | C14: 84.8 | D14: 89.4 | E14: 89.4 | F14: 89.4 | G14: 89.4 | H14: 87.4 | I14: 87.4 | J14: 87.2 | K14: =99-(24*0.4) -> 89.4 | L14: 89.4 | M14: 86

Sheet DADOS WORD DOC (NAO ALTERAR)
A1: DATA | B1: CLIENTE | C1: LOCALIZAÇÃO | D1: POTFABRICA | E1: INST | F1: INJ | G1: REGISTO | H1: POTINSTALADA | I1: PNOM | J1: PLIGAÇÃO | K1: NPAINEIS | L1: NINV | M1: PONTOINJEÇÃO | N1: PTINJ | O1: LOCALINST | P1: HOMOPOLAR | Q1: HOMOPOLAR1 | R1: EXCEDENTE | S1: EXCEDENTE1 | T1: INVPNOM | U1: INVMAXAPPARENT | V1: NMPPT | W1: NLIGAÇÕES | X1: MAXCURRMPPT | Y1: SCCURRMPPT | Z1: VNOMINPUT | AA1: VMAXINPUT | AB1: VMININPUT | AC1: VMPPMIN | AD1: VMPPMAX | AE1: MPPTRANGE | AF1: NOMCURROUT | AG1: MAXCURROUT | AH1: INVMODEL | AI1: INVBRAND | AJ1: INVPNOM2 | AK1: INVMAXAPPARENT2 | AL1: NMPPT2 | AM1: NLIGAÇÕES2 | AN1: MAXCURRMPPT2 | AO1: SCCURRMPPT2 | AP1: VNOMINPUT2 | AQ1: VMAXINPUT2 | AR1: VMININPUT2 | AS1: VMPPMIN2 | AT1: VMPPMAX2 | AU1: MPPTRANGE2 | AV1: NOMCURROUT2 | AW1: MAXCURROUT2 | AX1: INVMODEL2 | AY1: INVBRAND2 | AZ1: PANELMODEL | BA1: PANELBRAND | BB1: POTPAINEL | BC1: NCELULAS | BD1: VNOM | BE1: INOM | BF1: ISC | BG1: VOC | BH1: COEFFVOC | BI1: COEFFISC | BJ1: COEFFPM | BK1: EFFPANEL | BL1: EFF25 | BM1: MAXTEMP | BN1: MINTEMP | BO1: TECNICO RESPONSAVEL | BP1: NOET | BQ1: NSTRINGS | BR1: NSRTINGS/INV | BS1: SIZESTRING | BT1: POTINPUT | BU1: Voc corr for tmax | BV1: Voc corr for tmin | BW1: Vdc corr for tmax | BX1: Pdc at tmax | BY1: maxstringsize | BZ1: minpanelspermppt | CA1: NpanelsforPtmax | CB1: currpermppt | CC1: stringvoltage | CD1: Nº CC | CE1: Telefone técnico | CF1: email técnico | CG1: NIF técnico | CH1: Nº DGEG | CI1: Nº OET | CJ1: Morada técnico | CK1: Código Postal técnico | CL1: Coordenada GPS | CM1: Telefone cliente | CN1: email cliente | CO1: NIF cliente | CP1: Tensão de alimentação (kV) | CQ1: Potência certificada (kW) | CR1: CPE | CS1: Tipo de empresa
A2: ='Dados (ALTERAR)'!C4 -> 46235 | B2: ='Dados (ALTERAR)'!C7 -> STA – Sociedade Transformadora de Alumínios S.A. | C2: ='Dados (ALTERAR)'!C8 -> R. Terramonte 771, Gueifães, 4470-122 Maia | D2: ='Dados (ALTERAR)'!G6 -> 0 | E2: =IF(I2<=30,"MCP","UPAC") -> UPAC | F2: =IF('Dados (ALTERAR)'!C22="Sim","UPAC com injeção na rede", "UPAC sem injeção na rede") -> UPAC sem injeção na rede | G2: ='Dados (ALTERAR)'!C19 -> 0 | H2: ='Dados (ALTERAR)'!C24 -> 34 | I2: ='Dados (ALTERAR)'!C20 -> 50 | J2: ='Dados (ALTERAR)'!C21 -> 34 | K2: ='Dados (ALTERAR)'!C25 -> 34 | L2: ='Dados (ALTERAR)'!C23 -> 34 | M2: ='Dados (ALTERAR)'!C27 -> Quadro de Entrada | N2: =IF(M2="Quadro Geral de Baixa Tensão","QGBT","QP") -> QP | O2: ='Dados (ALTERAR)'!C26 -> 0 | P2: =IF(I2>250,"superior","inferior") -> inferior | Q2: =IF(AND(I2>250,'Dados (ALTERAR)'!C22="Sim"),"foi",IF(AND(I2>250,'Dados (ALTERAR)'!C22="Não"),"mas sendo sem injeção na rede, não foi",IF(I2<250,"não foi"))) -> não foi | R2: =IF('Dados (ALTERAR)'!C22="Sim","será","não será") -> não será | S2: =IF('Dados (ALTERAR)'!C22="Sim","poderá","não poderá") -> não poderá | T2: ='Dados (ALTERAR)'!C49 -> 8 | U2: ='Dados (ALTERAR)'!C48 -> 8.8 | V2: ='Dados (ALTERAR)'!C50 -> 3 | W2: ='Dados (ALTERAR)'!C51 -> 1 | X2: ='Dados (ALTERAR)'!C52 -> 16 | Y2: ='Dados (ALTERAR)'!C53 -> 20 | Z2: ='Dados (ALTERAR)'!C54 -> 350 | AA2: ='Dados (ALTERAR)'!C55 -> 600 | AB2: ='Dados (ALTERAR)'!C56 -> 100 | AC2: =_xlfn.CONCAT('Dados (ALTERAR)'!C57) -> 50 | AD2: =_xlfn.CONCAT('Dados (ALTERAR)'!C58) -> 550 | AE2: =_xlfn.CONCAT('Dados (ALTERAR)'!C57, " - ",'Dados (ALTERAR)'!C58) -> 50 - 550 | AF2: ='Dados (ALTERAR)'!C59 -> 36.4 | AG2: ='Dados (ALTERAR)'!C60 -> 40 | AH2: ='Dados (ALTERAR)'!C47 -> SigenStor EC 8.0 SP | AI2: ='Dados (ALTERAR)'!C46 -> Huawei | AJ2: ='Dados (ALTERAR)'!C67 -> 8 | AK2: ='Dados (ALTERAR)'!C66 -> 8.8 | AL2: ='Dados (ALTERAR)'!C68 -> 3 | AM2: ='Dados (ALTERAR)'!C69 -> 1 | AN2: ='Dados (ALTERAR)'!C70 -> 16 | AO2: ='Dados (ALTERAR)'!C71 -> 20 | AP2: ='Dados (ALTERAR)'!C72 -> 350 | AQ2: ='Dados (ALTERAR)'!C73 -> 600 | AR2: ='Dados (ALTERAR)'!C74 -> 100 | AS2: =_xlfn.CONCAT('Dados (ALTERAR)'!C75) -> 50 | AT2: =_xlfn.CONCAT('Dados (ALTERAR)'!C76) -> 550 | AU2: =_xlfn.CONCAT('Dados (ALTERAR)'!C75, " - ",'Dados (ALTERAR)'!C76) -> 50 - 550 | AV2: ='Dados (ALTERAR)'!C77 -> 36.4 | AW2: ='Dados (ALTERAR)'!C79 -> 98 | AX2: ='Dados (ALTERAR)'!C65 -> SigenStor EC 8.0 SP | AY2: ='Dados (ALTERAR)'!C64 -> Huawei | AZ2: ='Dados (ALTERAR)'!C31 -> RSM144-9-565BNDG-585BNDG | BA2: ='Dados (ALTERAR)'!C30 -> Risen | BB2: ='Dados (ALTERAR)'!C32 -> 585 | BC2: ='Dados (ALTERAR)'!C33 -> 144 | BD2: ='Dados (ALTERAR)'!C34 -> 44 | BE2: ='Dados (ALTERAR)'!C35 -> 13.32 | BF2: ='Dados (ALTERAR)'!C37 -> 14.18 | BG2: ='Dados (ALTERAR)'!C36 -> 52.37 | BH2: ='Dados (ALTERAR)'!C38 -> -0.25 | BI2: ='Dados (ALTERAR)'!C39 -> 0.046 | BJ2: ='Dados (ALTERAR)'!C40 -> -0.29 | BK2: ='Dados (ALTERAR)'!C42 -> 22.7 | BL2: ='Dados (ALTERAR)'!C43 -> 89.4 | BM2: 70 | BN2: ='Dados (ALTERAR)'!C41 -> -40 | BO2: ='Dados (ALTERAR)'!C2 -> Ricardo Miguel Modesto Louro | BP2: ='Dados (ALTERAR)'!C3 -> 31306 | BQ2: ='Dados (ALTERAR)'!G46 -> 2 | BR2: =BQ2/L2 -> 0.058823529 | BS2: ='Dados (ALTERAR)'!G47 -> 0 | BT2: =BS2*BR2*BX2/1000 -> 0 | BU2: =$BG$2*(1+((BM2-25)/100)*$BH$2) -> 46.478375 | BV2: =$BG$2*(1+((BN2-25)/100)*$BH$2) -> 60.880125 | BW2: =$BD$2*(1+((BM2-25)/100)*$BH$2) -> 39.05 | BX2: =$BB$2*(1+((BM2-25)/100)*$BJ$2) -> 508.6575 | BY2: =ROUNDDOWN(AA2/BV2,0) -> 9 | BZ2: =ROUNDUP(AC2/BU2,0) -> 2 | CA2: =ROUNDDOWN(U2*1000/BX2,0) -> 17 | CB2: =BE2*W2/V2 -> 4.44 | CC2: =BD2*BS2 -> 0 | CD2: =VLOOKUP(CD1,'Técnico responsável'!$A$2:$E$9,MATCH('Dados (ALTERAR)'!$C$2,'Técnico responsável'!$A$1:$E$1,0),FALSE) -> 15814378 | CE2: =VLOOKUP(CE1,'Técnico responsável'!$A$2:$E$9,MATCH('Dados (ALTERAR)'!$C$2,'Técnico responsável'!$A$1:$E$1,0),FALSE) -> 937865788 | CF2: =VLOOKUP(CF1,'Técnico responsável'!$A$2:$E$9,MATCH('Dados (ALTERAR)'!$C$2,'Técnico responsável'!$A$1:$E$1,0),FALSE) -> ricardo.louro@solcor.pt | CG2: =VLOOKUP(CG1,'Técnico responsável'!$A$2:$E$9,MATCH('Dados (ALTERAR)'!$C$2,'Técnico responsável'!$A$1:$E$1,0),FALSE) -> 238600912 | CH2: =VLOOKUP(CH1,'Técnico responsável'!$A$2:$E$9,MATCH('Dados (ALTERAR)'!$C$2,'Técnico responsável'!$A$1:$E$1,0),FALSE) -> 88638 | CI2: =VLOOKUP(CI1,'Técnico responsável'!$A$2:$E$9,MATCH('Dados (ALTERAR)'!$C$2,'Técnico responsável'!$A$1:$E$1,0),FALSE) -> 31306 | CJ2: =VLOOKUP(CJ1,'Técnico responsável'!$A$2:$E$9,MATCH('Dados (ALTERAR)'!$C$2,'Técnico responsável'!$A$1:$E$1,0),FALSE) -> Avenida Almirante Reis 54, 3º Andar | CK2: =VLOOKUP(CK1,'Técnico responsável'!$A$2:$E$9,MATCH('Dados (ALTERAR)'!$C$2,'Técnico responsável'!$A$1:$E$1,0),FALSE) -> 1150-019 Lisboa | CL2: ='Dados (ALTERAR)'!C9 -> 41.20583976494613, -8.603993799425119 | CM2: ='Dados (ALTERAR)'!C10 -> 912101956 | CN2: ='Dados (ALTERAR)'!C11 -> Branco@sofi.pt | CO2: ='Dados (ALTERAR)'!C12 -> 0 | CP2: ='Dados (ALTERAR)'!C14 -> 0 | CQ2: ='Dados (ALTERAR)'!C15 -> 0 | CR2: ='Dados (ALTERAR)'!C13 -> 0 | CS2: ='Dados (ALTERAR)'!C16 -> 0

Sheet INVERSORES (NÃO ALTERAR)
A1: Caracteristicas | B1: SUN2000-5KTL-L1 | C1: SUN2000-6KTL-L1 | D1: SUN2000-10K-MAP0 | E1: SUN2000-12K-MAP0 | F1: SUN2000-3KTL-M1 HC | G1: SUN2000-4KTL-M1 HC | H1: SUN2000-5KTL-M1 HC | I1: SUN2000-6KTL-M1 HC | J1: SUN2000-8KTL-M1 HC | K1: SUN2000-10KT-M1 HC | L1: SUN2000-12K-MB0 | M1: SUN2000-15K-MB0 | N1: SUN2000-17KTL-MB0 | O1: SUN2000-20K-MB0 | P1: SUN2000-25K-MB0 | Q1: SUN2000-30KTL-M3 | R1: SUN2000-36KTL-M3 | S1: SUN2000-40KTL-M3 | T1: SUN2000-50KTL-M3 | U1: SUN2000-100KTL-M2 | V1: SUN2000-115KTL-M2 | W1: SUN2000-150K-MG0 | X1: SigenStor EC 5.0 TP | Y1: SigenStor EC 6.0 TP | Z1: SigenStor EC 8.0 TP | AA1: SigenStor EC 10.0 TP | AB1: SigenStor EC 12.0 TP | AC1: SigenStor EC 15.0 TP | AD1: SigenStor EC 17.0 TP | AE1: SigenStor EC 20.0 TP | AF1: SigenStor EC 25.0 TP | AG1: SigenStor EC 30.0 TP | AH1: PV 50 M1-HYA | AI1: PV 60-M1-HYA | AJ1: PV 80 M1-HYA | AK1: PV 100 M1-HYA | AL1: PV 110-M1-HYA | AM1: PV 125-M1-HYA | AN1: PV 50 M1 | AO1: PV 60 M1 | AP1: PV 80 M1 | AQ1: PV 100 M1 | AR1: PV 110 M1 | AS1: PV 125 M1 | AT1: PV 50 M1-HYB | AU1: PV 60-M1-HYB | AV1: PV 80 M1-HYB | AW1: PV 100 M1-HYB | AX1: PV 110-M1-HYB | AY1: PV 125-M1-HYB | AZ1: SigenStor EC 3.0 SP | BA1: SigenStor EC 3.6 SP | BB1: SigenStor EC 4.0 SP | BC1: SigenStor EC 5.0 SP | BD1: SigenStor EC 6.0 SP | BE1: SigenStor EC 8.0 SP | BF1: SigenStor EC 10.0 SP | BG1: SigenStor EC 12.0 SP
A2: Potência ativa máxima (cosφ=1) | B2: 5 | C2: 6 | D2: 11 | E2: 13.2 | F2: 3.3 | G2: 4.4 | H2: 5.5 | I2: 6.6 | J2: 8.8 | K2: 11 | L2: 13.2 | M2: 16.5 | N2: 18.7 | O2: 22 | P2: 27.5 | Q2: 33 | R2: 40 | S2: 44 | T2: 55 | U2: 110 | V2: 125 | W2: 165 | X2: 5.5 | Y2: 6.6 | Z2: 8.8 | AA2: 11 | AB2: 13.2 | AC2: 16.5 | AD2: 18.7 | AE2: 22 | AF2: 27.5 | AG2: 33 | AH2: 55 | AI2: 66 | AJ2: 88 | AK2: 110 | AL2: 121 | AM2: 137.5 | AN2: 55 | AO2: 66 | AP2: 88 | AQ2: 110 | AR2: 121 | AS2: 137.5 | AT2: 55 | AU2: 66 | AV2: 88 | AW2: 110 | AX2: 121 | AY2: 137.5 | AZ2: 3.3 | BA2: 3.68 | BB2: 4.4 | BC2: 5.5 | BD2: 6.6 | BE2: 8.8 | BF2: 11 | BG2: 12
A3: Potência nominal por inversor | B3: 5 | C3: 6 | D3: 10 | E3: 12 | F3: 3 | G3: 4 | H3: 5 | I3: 6 | J3: 8 | K3: 10 | L3: 12 | M3: 15 | N3: 17 | O3: 20 | P3: 25 | Q3: 30 | R3: 36 | S3: 40 | T3: 50 | U3: 100 | V3: 115 | W3: 150 | X3: 5 | Y3: 6 | Z3: 8 | AA3: 10 | AB3: 12 | AC3: 15 | AD3: 17 | AE3: 20 | AF3: 25 | AG3: 30 | AH3: 50 | AI3: 60 | AJ3: 80 | AK3: 100 | AL3: 110 | AM3: 125 | AN3: 50 | AO3: 60 | AP3: 80 | AQ3: 100 | AR3: 110 | AS3: 125 | AT3: 50 | AU3: 60 | AV3: 80 | AW3: 100 | AX3: 110 | AY3: 125 | AZ3: 3 | BA3: 3.68 | BB3: 4 | BC3: 5 | BD3: 6 | BE3: 8 | BF3: 10 | BG3: 12
A4: Nº de MPPT | B4: 2 | C4: 2 | D4: 2 | E4: 2 | F4: 2 | G4: 2 | H4: 2 | I4: 2 | J4: 2 | K4: 2 | L4: 2 | M4: 2 | N4: 2 | O4: 2 | P4: 2 | Q4: 4 | R4: 4 | S4: 4 | T4: 4 | U4: 10 | V4: 10 | W4: 7 | X4: 2 | Y4: 2 | Z4: 2 | AA4: 3 | AB4: 3 | AC4: 3 | AD4: 4 | AE4: 4 | AF4: 4 | AG4: 4 | AH4: 4 | AI4: 5 | AJ4: 6 | AK4: 8 | AL4: 8 | AM4: 8 | AN4: 4 | AO4: 5 | AP4: 6 | AQ4: 8 | AR4: 8 | AS4: 8 | AT4: 4 | AU4: 5 | AV4: 6 | AW4: 8 | AX4: 8 | AY4: 8 | AZ4: 2 | BA4: 2 | BB4: 2 | BC4: 2 | BD4: 2 | BE4: 3 | BF4: 4 | BG4: 4
A5: Nº de Ligações CC | B5: 1 | C5: 2 | D5: 1 | E5: 1 | F5: 1 | G5: 1 | H5: 1 | I5: 1 | J5: 1 | K5: 1 | L5: 2 | M5: 2 | N5: 2 | O5: 2 | P5: 2 | Q5: 2 | R5: 2 | S5: 2 | T5: 2 | U5: 2 | V5: 2 | W5: 3 | X5: 1 | Y5: 1 | Z5: 1 | AA5: 1 | AB5: 1 | AC5: 1 | AD5: 1 | AE5: 1 | AF5: 1 | AG5: 1 | AH5: 2 | AI5: 2 | AJ5: 2 | AK5: 2 | AL5: 2 | AM5: 2 | AN5: 2 | AO5: 2 | AP5: 2 | AQ5: 2 | AR5: 2 | AS5: 2 | AT5: 2 | AU5: 2 | AV5: 2 | AW5: 2 | AX5: 2 | AY5: 2 | AZ5: 1 | BA5: 1 | BB5: 1 | BC5: 1 | BD5: 1 | BE5: 1 | BF5: 1 | BG5: 1
A6: Corrente máxima por MPPT (A) | B6: 12.5 | C6: 12.5 | D6: 16 | E6: 16 | F6: 11 | G6: 11 | H6: 11 | I6: 11 | J6: 11 | K6: 11 | L6: 30 | M6: 30 | N6: 30 | O6: 30 | P6: 30 | Q6: 26 | R6: 26 | S6: 26 | T6: 30 | U6: 20 | V6: 20 | W6: 23 | X6: 16 | Y6: 16 | Z6: 16 | AA6: 16 | AB6: 16 | AC6: 16 | AD6: 16 | AE6: 16 | AF6: 16 | AG6: 16 | AH6: 40 | AI6: 40 | AJ6: 40 | AK6: 40 | AL6: 40 | AM6: 40 | AN6: 40 | AO6: 40 | AP6: 40 | AQ6: 40 | AR6: 40 | AS6: 40 | AT6: 40 | AU6: 40 | AV6: 40 | AW6: 40 | AX6: 40 | AY6: 40 | AZ6: 16 | BA6: 16 | BB6: 16 | BC6: 16 | BD6: 16 | BE6: 16 | BF6: 16 | BG6: 16
A7: Corrente de curto-circuito por MPPT (A) | B7: 18 | C7: 18 | D7: 22 | E7: 22 | F7: 15 | G7: 15 | H7: 15 | I7: 15 | J7: 15 | K7: 15 | L7: 40 | M7: 40 | N7: 40 | O7: 40 | P7: 40 | Q7: 40 | R7: 40 | S7: 40 | T7: 40 | U7: 40 | V7: 40 | W7: 66 | X7: 20 | Y7: 20 | Z7: 20 | AA7: 20 | AB7: 20 | AC7: 20 | AD7: 20 | AE7: 20 | AF7: 20 | AG7: 20 | AH7: 60 | AI7: 60 | AJ7: 60 | AK7: 60 | AL7: 60 | AM7: 60 | AN7: 60 | AO7: 60 | AP7: 60 | AQ7: 60 | AR7: 60 | AS7: 60 | AT7: 60 | AU7: 60 | AV7: 60 | AW7: 60 | AX7: 60 | AY7: 60 | AZ7: 20 | BA7: 20 | BB7: 20 | BC7: 20 | BD7: 20 | BE7: 20 | BF7: 20 | BG7: 20
A8: Tensão nominal de entrada (V) | B8: 360 | C8: 360 | D8: 600 | E8: 600 | F8: 600 | G8: 600 | H8: 600 | I8: 600 | J8: 600 | K8: 600 | L8: 600 | M8: 600 | N8: 600 | O8: 600 | P8: 600 | Q8: 600 | R8: 600 | S8: 600 | T8: 600 | U8: 600 | V8: 600 | W8: 600 | X8: 600 | Y8: 600 | Z8: 600 | AA8: 600 | AB8: 600 | AC8: 600 | AD8: 600 | AE8: 600 | AF8: 600 | AG8: 600 | AH8: 600 | AI8: 600 | AJ8: 600 | AK8: 600 | AL8: 600 | AM8: 600 | AN8: 600 | AO8: 600 | AP8: 600 | AQ8: 600 | AR8: 600 | AS8: 600 | AT8: 600 | AU8: 600 | AV8: 600 | AW8: 600 | AX8: 600 | AY8: 600 | AZ8: 350 | BA8: 350 | BB8: 350 | BC8: 350 | BD8: 350 | BE8: 350 | BF8: 350 | BG8: 350
A9: Tensão máxima de entrada (V) | B9: 600 | C9: 600 | D9: 1100 | E9: 1100 | F9: 1100 | G9: 1100 | H9: 1100 | I9: 1100 | J9: 1100 | K9: 1100 | L9: 1100 | M9: 1100 | N9: 1100 | O9: 1100 | P9: 1100 | Q9: 1100 | R9: 1100 | S9: 1100 | T9: 1100 | U9: 1100 | V9: 1100 | W9: 1100 | X9: 1100 | Y9: 1100 | Z9: 1100 | AA9: 1100 | AB9: 1100 | AC9: 1100 | AD9: 1100 | AE9: 1100 | AF9: 1100 | AG9: 1100 | AH9: 1100 | AI9: 1100 | AJ9: 1100 | AK9: 1100 | AL9: 1100 | AM9: 1100 | AN9: 1100 | AO9: 1100 | AP9: 1100 | AQ9: 1100 | AR9: 1100 | AS9: 1100 | AT9: 1100 | AU9: 1100 | AV9: 1100 | AW9: 1100 | AX9: 1100 | AY9: 1100 | AZ9: 600 | BA9: 600 | BB9: 600 | BC9: 600 | BD9: 600 | BE9: 600 | BF9: 600 | BG9: 600
A10: Tensão de arranque (V) | B10: 100 | C10: 100 | D10: 160 | E10: 160 | F10: 200 | G10: 200 | H10: 200 | I10: 200 | J10: 200 | K10: 200 | L10: 200 | M10: 200 | N10: 200 | O10: 200 | P10: 200 | Q10: 200 | R10: 200 | S10: 200 | T10: 200 | U10: 200 | V10: 200 | W10: 200 | X10: 180 | Y10: 180 | Z10: 180 | AA10: 180 | AB10: 180 | AC10: 180 | AD10: 180 | AE10: 180 | AF10: 180 | AG10: 180 | AH10: 180 | AI10: 180 | AJ10: 180 | AK10: 180 | AL10: 180 | AM10: 180 | AN10: 180 | AO10: 180 | AP10: 180 | AQ10: 180 | AR10: 180 | AS10: 180 | AT10: 180 | AU10: 180 | AV10: 180 | AW10: 180 | AX10: 180 | AY10: 180 | AZ10: 100 | BA10: 100 | BB10: 100 | BC10: 100 | BD10: 100 | BE10: 100 | BF10: 100 | BG10: 100
A11: Tensão minima de entrada MPP (V) | B11: 90 | C11: 90 | D11: 160 | E11: 160 | F11: 140 | G11: 140 | H11: 140 | I11: 140 | J11: 140 | K11: 140 | L11: 200 | M11: 200 | N11: 200 | O11: 200 | P11: 200 | Q11: 200 | R11: 200 | S11: 200 | T11: 200 | U11: 200 | V11: 200 | W11: 200 | X11: 160 | Y11: 160 | Z11: 160 | AA11: 160 | AB11: 160 | AC11: 160 | AD11: 160 | AE11: 160 | AF11: 160 | AG11: 160 | AH11: 160 | AI11: 160 | AJ11: 160 | AK11: 160 | AL11: 160 | AM11: 160 | AN11: 160 | AO11: 160 | AP11: 160 | AQ11: 160 | AR11: 160 | AS11: 160 | AT11: 160 | AU11: 160 | AV11: 160 | AW11: 160 | AX11: 160 | AY11: 160 | AZ11: 50 | BA11: 50 | BB11: 50 | BC11: 50 | BD11: 50 | BE11: 50 | BF11: 50 | BG11: 50
A12: Tensão máxima de entrada MPP (V) | B12: 560 | C12: 560 | D12: 1000 | E12: 1000 | F12: 980 | G12: 980 | H12: 980 | I12: 980 | J12: 980 | K12: 980 | L12: 1000 | M12: 1000 | N12: 1000 | O12: 1000 | P12: 1000 | Q12: 1000 | R12: 1000 | S12: 1000 | T12: 1000 | U12: 1000 | V12: 1000 | W12: 1000 | X12: 1000 | Y12: 1000 | Z12: 1000 | AA12: 1000 | AB12: 1000 | AC12: 1000 | AD12: 1000 | AE12: 1000 | AF12: 1000 | AG12: 1000 | AH12: 1000 | AI12: 1000 | AJ12: 1000 | AK12: 1000 | AL12: 1000 | AM12: 1000 | AN12: 1000 | AO12: 1000 | AP12: 1000 | AQ12: 1000 | AR12: 1000 | AS12: 1000 | AT12: 1000 | AU12: 1000 | AV12: 1000 | AW12: 1000 | AX12: 1000 | AY12: 1000 | AZ12: 550 | BA12: 550 | BB12: 550 | BC12: 550 | BD12: 550 | BE12: 550 | BF12: 550 | BG12: 550
